actualizar_estado_cliente_crm
Traceback (most recent call last):
  File "/home/ronny/Escritorio/Rama_Ronny/sistema_django_postgresql/manage.py", line 22, in <module>
    main()
  File "/home/ronny/Escritorio/Rama_Ronny/sistema_django_postgresql/manage.py", line 18, in main
    execute_from_command_line(sys.argv)
  File "/home/ronny/Escritorio/Rama_Ronny/entornos/sistema/lib/python3.10/site-packages/django/core/management/__init__.py", line 419, in execute_from_command_line
    utility.execute()
  File "/home/ronny/Escritorio/Rama_Ronny/entornos/sistema/lib/python3.10/site-packages/django/core/management/__init__.py", line 413, in execute
    self.fetch_command(subcommand).run_from_argv(self.argv)
  File "/home/ronny/Escritorio/Rama_Ronny/entornos/sistema/lib/python3.10/site-packages/django/core/management/base.py", line 354, in run_from_argv
    self.execute(*args, **cmd_options)
  File "/home/ronny/Escritorio/Rama_Ronny/entornos/sistema/lib/python3.10/site-packages/django/core/management/base.py", line 398, in execute
    output = self.handle(*args, **options)
  File "/home/ronny/Escritorio/Rama_Ronny/entornos/sistema/lib/python3.10/site-packages/django_crontab/management/commands/crontab.py", line 29, in handle
    Crontab().run_job(options['jobhash'])
  File "/home/ronny/Escritorio/Rama_Ronny/entornos/sistema/lib/python3.10/site-packages/django_crontab/crontab.py", line 126, in run_job
    job = self.__get_job_by_hash(job_hash)
  File "/home/ronny/Escritorio/Rama_Ronny/entornos/sistema/lib/python3.10/site-packages/django_crontab/crontab.py", line 171, in __get_job_by_hash
    raise RuntimeError(
RuntimeError: No job with hash 2b81aae0b31c33ee9e384b4c1a5e8f01 found. It seems the crontab is out of sync with your settings.CRONJOBS. Run "python manage.py crontab add" again to resolve this issue!
Traceback (most recent call last):
  File "/home/ronny/Escritorio/Rama_Ronny/sistema_django_postgresql/manage.py", line 22, in <module>
    main()
  File "/home/ronny/Escritorio/Rama_Ronny/sistema_django_postgresql/manage.py", line 18, in main
    execute_from_command_line(sys.argv)
  File "/home/ronny/Escritorio/Rama_Ronny/entornos/sistema/lib/python3.10/site-packages/django/core/management/__init__.py", line 419, in execute_from_command_line
    utility.execute()
  File "/home/ronny/Escritorio/Rama_Ronny/entornos/sistema/lib/python3.10/site-packages/django/core/management/__init__.py", line 413, in execute
    self.fetch_command(subcommand).run_from_argv(self.argv)
  File "/home/ronny/Escritorio/Rama_Ronny/entornos/sistema/lib/python3.10/site-packages/django/core/management/base.py", line 354, in run_from_argv
    self.execute(*args, **cmd_options)
  File "/home/ronny/Escritorio/Rama_Ronny/entornos/sistema/lib/python3.10/site-packages/django/core/management/base.py", line 398, in execute
    output = self.handle(*args, **options)
  File "/home/ronny/Escritorio/Rama_Ronny/entornos/sistema/lib/python3.10/site-packages/django_crontab/management/commands/crontab.py", line 29, in handle
    Crontab().run_job(options['jobhash'])
  File "/home/ronny/Escritorio/Rama_Ronny/entornos/sistema/lib/python3.10/site-packages/django_crontab/crontab.py", line 126, in run_job
    job = self.__get_job_by_hash(job_hash)
  File "/home/ronny/Escritorio/Rama_Ronny/entornos/sistema/lib/python3.10/site-packages/django_crontab/crontab.py", line 171, in __get_job_by_hash
    raise RuntimeError(
RuntimeError: No job with hash 2b81aae0b31c33ee9e384b4c1a5e8f01 found. It seems the crontab is out of sync with your settings.CRONJOBS. Run "python manage.py crontab add" again to resolve this issue!
Traceback (most recent call last):
  File "/home/ronny/Escritorio/Rama_Ronny/sistema_django_postgresql/manage.py", line 22, in <module>
    main()
  File "/home/ronny/Escritorio/Rama_Ronny/sistema_django_postgresql/manage.py", line 18, in main
    execute_from_command_line(sys.argv)
  File "/home/ronny/Escritorio/Rama_Ronny/entornos/sistema/lib/python3.10/site-packages/django/core/management/__init__.py", line 419, in execute_from_command_line
    utility.execute()
  File "/home/ronny/Escritorio/Rama_Ronny/entornos/sistema/lib/python3.10/site-packages/django/core/management/__init__.py", line 413, in execute
    self.fetch_command(subcommand).run_from_argv(self.argv)
  File "/home/ronny/Escritorio/Rama_Ronny/entornos/sistema/lib/python3.10/site-packages/django/core/management/base.py", line 354, in run_from_argv
    self.execute(*args, **cmd_options)
  File "/home/ronny/Escritorio/Rama_Ronny/entornos/sistema/lib/python3.10/site-packages/django/core/management/base.py", line 398, in execute
    output = self.handle(*args, **options)
  File "/home/ronny/Escritorio/Rama_Ronny/entornos/sistema/lib/python3.10/site-packages/django_crontab/management/commands/crontab.py", line 29, in handle
    Crontab().run_job(options['jobhash'])
  File "/home/ronny/Escritorio/Rama_Ronny/entornos/sistema/lib/python3.10/site-packages/django_crontab/crontab.py", line 126, in run_job
    job = self.__get_job_by_hash(job_hash)
  File "/home/ronny/Escritorio/Rama_Ronny/entornos/sistema/lib/python3.10/site-packages/django_crontab/crontab.py", line 171, in __get_job_by_hash
    raise RuntimeError(
RuntimeError: No job with hash 2b81aae0b31c33ee9e384b4c1a5e8f01 found. It seems the crontab is out of sync with your settings.CRONJOBS. Run "python manage.py crontab add" again to resolve this issue!
Traceback (most recent call last):
  File "/home/ronny/Escritorio/Rama_Ronny/sistema_django_postgresql/manage.py", line 22, in <module>
    main()
  File "/home/ronny/Escritorio/Rama_Ronny/sistema_django_postgresql/manage.py", line 18, in main
    execute_from_command_line(sys.argv)
  File "/home/ronny/Escritorio/Rama_Ronny/entornos/sistema/lib/python3.10/site-packages/django/core/management/__init__.py", line 419, in execute_from_command_line
    utility.execute()
  File "/home/ronny/Escritorio/Rama_Ronny/entornos/sistema/lib/python3.10/site-packages/django/core/management/__init__.py", line 413, in execute
    self.fetch_command(subcommand).run_from_argv(self.argv)
  File "/home/ronny/Escritorio/Rama_Ronny/entornos/sistema/lib/python3.10/site-packages/django/core/management/base.py", line 354, in run_from_argv
    self.execute(*args, **cmd_options)
  File "/home/ronny/Escritorio/Rama_Ronny/entornos/sistema/lib/python3.10/site-packages/django/core/management/base.py", line 398, in execute
    output = self.handle(*args, **options)
  File "/home/ronny/Escritorio/Rama_Ronny/entornos/sistema/lib/python3.10/site-packages/django_crontab/management/commands/crontab.py", line 29, in handle
    Crontab().run_job(options['jobhash'])
  File "/home/ronny/Escritorio/Rama_Ronny/entornos/sistema/lib/python3.10/site-packages/django_crontab/crontab.py", line 126, in run_job
    job = self.__get_job_by_hash(job_hash)
  File "/home/ronny/Escritorio/Rama_Ronny/entornos/sistema/lib/python3.10/site-packages/django_crontab/crontab.py", line 171, in __get_job_by_hash
    raise RuntimeError(
RuntimeError: No job with hash 2b81aae0b31c33ee9e384b4c1a5e8f01 found. It seems the crontab is out of sync with your settings.CRONJOBS. Run "python manage.py crontab add" again to resolve this issue!
Traceback (most recent call last):
  File "/home/ronny/Escritorio/Rama_Ronny/sistema_django_postgresql/manage.py", line 22, in <module>
    main()
  File "/home/ronny/Escritorio/Rama_Ronny/sistema_django_postgresql/manage.py", line 18, in main
    execute_from_command_line(sys.argv)
  File "/home/ronny/Escritorio/Rama_Ronny/entornos/sistema/lib/python3.10/site-packages/django/core/management/__init__.py", line 419, in execute_from_command_line
    utility.execute()
  File "/home/ronny/Escritorio/Rama_Ronny/entornos/sistema/lib/python3.10/site-packages/django/core/management/__init__.py", line 413, in execute
    self.fetch_command(subcommand).run_from_argv(self.argv)
  File "/home/ronny/Escritorio/Rama_Ronny/entornos/sistema/lib/python3.10/site-packages/django/core/management/base.py", line 354, in run_from_argv
    self.execute(*args, **cmd_options)
  File "/home/ronny/Escritorio/Rama_Ronny/entornos/sistema/lib/python3.10/site-packages/django/core/management/base.py", line 398, in execute
    output = self.handle(*args, **options)
  File "/home/ronny/Escritorio/Rama_Ronny/entornos/sistema/lib/python3.10/site-packages/django_crontab/management/commands/crontab.py", line 29, in handle
    Crontab().run_job(options['jobhash'])
  File "/home/ronny/Escritorio/Rama_Ronny/entornos/sistema/lib/python3.10/site-packages/django_crontab/crontab.py", line 126, in run_job
    job = self.__get_job_by_hash(job_hash)
  File "/home/ronny/Escritorio/Rama_Ronny/entornos/sistema/lib/python3.10/site-packages/django_crontab/crontab.py", line 171, in __get_job_by_hash
    raise RuntimeError(
RuntimeError: No job with hash 2b81aae0b31c33ee9e384b4c1a5e8f01 found. It seems the crontab is out of sync with your settings.CRONJOBS. Run "python manage.py crontab add" again to resolve this issue!
Traceback (most recent call last):
  File "/home/ronny/Escritorio/Rama_Ronny/sistema_django_postgresql/manage.py", line 22, in <module>
    main()
  File "/home/ronny/Escritorio/Rama_Ronny/sistema_django_postgresql/manage.py", line 18, in main
    execute_from_command_line(sys.argv)
  File "/home/ronny/Escritorio/Rama_Ronny/entornos/sistema/lib/python3.10/site-packages/django/core/management/__init__.py", line 419, in execute_from_command_line
    utility.execute()
  File "/home/ronny/Escritorio/Rama_Ronny/entornos/sistema/lib/python3.10/site-packages/django/core/management/__init__.py", line 413, in execute
    self.fetch_command(subcommand).run_from_argv(self.argv)
  File "/home/ronny/Escritorio/Rama_Ronny/entornos/sistema/lib/python3.10/site-packages/django/core/management/base.py", line 354, in run_from_argv
    self.execute(*args, **cmd_options)
  File "/home/ronny/Escritorio/Rama_Ronny/entornos/sistema/lib/python3.10/site-packages/django/core/management/base.py", line 398, in execute
    output = self.handle(*args, **options)
  File "/home/ronny/Escritorio/Rama_Ronny/entornos/sistema/lib/python3.10/site-packages/django_crontab/management/commands/crontab.py", line 29, in handle
    Crontab().run_job(options['jobhash'])
  File "/home/ronny/Escritorio/Rama_Ronny/entornos/sistema/lib/python3.10/site-packages/django_crontab/crontab.py", line 126, in run_job
    job = self.__get_job_by_hash(job_hash)
  File "/home/ronny/Escritorio/Rama_Ronny/entornos/sistema/lib/python3.10/site-packages/django_crontab/crontab.py", line 171, in __get_job_by_hash
    raise RuntimeError(
RuntimeError: No job with hash 2b81aae0b31c33ee9e384b4c1a5e8f01 found. It seems the crontab is out of sync with your settings.CRONJOBS. Run "python manage.py crontab add" again to resolve this issue!
Traceback (most recent call last):
  File "/home/ronny/Escritorio/Rama_Ronny/sistema_django_postgresql/manage.py", line 22, in <module>
    main()
  File "/home/ronny/Escritorio/Rama_Ronny/sistema_django_postgresql/manage.py", line 18, in main
    execute_from_command_line(sys.argv)
  File "/home/ronny/Escritorio/Rama_Ronny/entornos/sistema/lib/python3.10/site-packages/django/core/management/__init__.py", line 419, in execute_from_command_line
    utility.execute()
  File "/home/ronny/Escritorio/Rama_Ronny/entornos/sistema/lib/python3.10/site-packages/django/core/management/__init__.py", line 413, in execute
    self.fetch_command(subcommand).run_from_argv(self.argv)
  File "/home/ronny/Escritorio/Rama_Ronny/entornos/sistema/lib/python3.10/site-packages/django/core/management/base.py", line 354, in run_from_argv
    self.execute(*args, **cmd_options)
  File "/home/ronny/Escritorio/Rama_Ronny/entornos/sistema/lib/python3.10/site-packages/django/core/management/base.py", line 398, in execute
    output = self.handle(*args, **options)
  File "/home/ronny/Escritorio/Rama_Ronny/entornos/sistema/lib/python3.10/site-packages/django_crontab/management/commands/crontab.py", line 29, in handle
    Crontab().run_job(options['jobhash'])
  File "/home/ronny/Escritorio/Rama_Ronny/entornos/sistema/lib/python3.10/site-packages/django_crontab/crontab.py", line 126, in run_job
    job = self.__get_job_by_hash(job_hash)
  File "/home/ronny/Escritorio/Rama_Ronny/entornos/sistema/lib/python3.10/site-packages/django_crontab/crontab.py", line 171, in __get_job_by_hash
    raise RuntimeError(
RuntimeError: No job with hash 2b81aae0b31c33ee9e384b4c1a5e8f01 found. It seems the crontab is out of sync with your settings.CRONJOBS. Run "python manage.py crontab add" again to resolve this issue!
Traceback (most recent call last):
  File "/home/ronny/Escritorio/Rama_Ronny/sistema_django_postgresql/manage.py", line 22, in <module>
    main()
  File "/home/ronny/Escritorio/Rama_Ronny/sistema_django_postgresql/manage.py", line 18, in main
    execute_from_command_line(sys.argv)
  File "/home/ronny/Escritorio/Rama_Ronny/entornos/sistema/lib/python3.10/site-packages/django/core/management/__init__.py", line 419, in execute_from_command_line
    utility.execute()
  File "/home/ronny/Escritorio/Rama_Ronny/entornos/sistema/lib/python3.10/site-packages/django/core/management/__init__.py", line 413, in execute
    self.fetch_command(subcommand).run_from_argv(self.argv)
  File "/home/ronny/Escritorio/Rama_Ronny/entornos/sistema/lib/python3.10/site-packages/django/core/management/base.py", line 354, in run_from_argv
    self.execute(*args, **cmd_options)
  File "/home/ronny/Escritorio/Rama_Ronny/entornos/sistema/lib/python3.10/site-packages/django/core/management/base.py", line 398, in execute
    output = self.handle(*args, **options)
  File "/home/ronny/Escritorio/Rama_Ronny/entornos/sistema/lib/python3.10/site-packages/django_crontab/management/commands/crontab.py", line 29, in handle
    Crontab().run_job(options['jobhash'])
  File "/home/ronny/Escritorio/Rama_Ronny/entornos/sistema/lib/python3.10/site-packages/django_crontab/crontab.py", line 126, in run_job
    job = self.__get_job_by_hash(job_hash)
  File "/home/ronny/Escritorio/Rama_Ronny/entornos/sistema/lib/python3.10/site-packages/django_crontab/crontab.py", line 171, in __get_job_by_hash
    raise RuntimeError(
RuntimeError: No job with hash 2b81aae0b31c33ee9e384b4c1a5e8f01 found. It seems the crontab is out of sync with your settings.CRONJOBS. Run "python manage.py crontab add" again to resolve this issue!
Traceback (most recent call last):
  File "/home/ronny/Escritorio/Rama_Ronny/sistema_django_postgresql/manage.py", line 22, in <module>
    main()
  File "/home/ronny/Escritorio/Rama_Ronny/sistema_django_postgresql/manage.py", line 18, in main
    execute_from_command_line(sys.argv)
  File "/home/ronny/Escritorio/Rama_Ronny/entornos/sistema/lib/python3.10/site-packages/django/core/management/__init__.py", line 419, in execute_from_command_line
    utility.execute()
  File "/home/ronny/Escritorio/Rama_Ronny/entornos/sistema/lib/python3.10/site-packages/django/core/management/__init__.py", line 413, in execute
    self.fetch_command(subcommand).run_from_argv(self.argv)
  File "/home/ronny/Escritorio/Rama_Ronny/entornos/sistema/lib/python3.10/site-packages/django/core/management/base.py", line 354, in run_from_argv
    self.execute(*args, **cmd_options)
  File "/home/ronny/Escritorio/Rama_Ronny/entornos/sistema/lib/python3.10/site-packages/django/core/management/base.py", line 398, in execute
    output = self.handle(*args, **options)
  File "/home/ronny/Escritorio/Rama_Ronny/entornos/sistema/lib/python3.10/site-packages/django_crontab/management/commands/crontab.py", line 29, in handle
    Crontab().run_job(options['jobhash'])
  File "/home/ronny/Escritorio/Rama_Ronny/entornos/sistema/lib/python3.10/site-packages/django_crontab/crontab.py", line 126, in run_job
    job = self.__get_job_by_hash(job_hash)
  File "/home/ronny/Escritorio/Rama_Ronny/entornos/sistema/lib/python3.10/site-packages/django_crontab/crontab.py", line 171, in __get_job_by_hash
    raise RuntimeError(
RuntimeError: No job with hash 2b81aae0b31c33ee9e384b4c1a5e8f01 found. It seems the crontab is out of sync with your settings.CRONJOBS. Run "python manage.py crontab add" again to resolve this issue!
Traceback (most recent call last):
  File "/home/ronny/Escritorio/Rama_Ronny/sistema_django_postgresql/manage.py", line 22, in <module>
    main()
  File "/home/ronny/Escritorio/Rama_Ronny/sistema_django_postgresql/manage.py", line 18, in main
    execute_from_command_line(sys.argv)
  File "/home/ronny/Escritorio/Rama_Ronny/entornos/sistema/lib/python3.10/site-packages/django/core/management/__init__.py", line 419, in execute_from_command_line
    utility.execute()
  File "/home/ronny/Escritorio/Rama_Ronny/entornos/sistema/lib/python3.10/site-packages/django/core/management/__init__.py", line 413, in execute
    self.fetch_command(subcommand).run_from_argv(self.argv)
  File "/home/ronny/Escritorio/Rama_Ronny/entornos/sistema/lib/python3.10/site-packages/django/core/management/base.py", line 354, in run_from_argv
    self.execute(*args, **cmd_options)
  File "/home/ronny/Escritorio/Rama_Ronny/entornos/sistema/lib/python3.10/site-packages/django/core/management/base.py", line 398, in execute
    output = self.handle(*args, **options)
  File "/home/ronny/Escritorio/Rama_Ronny/entornos/sistema/lib/python3.10/site-packages/django_crontab/management/commands/crontab.py", line 29, in handle
    Crontab().run_job(options['jobhash'])
  File "/home/ronny/Escritorio/Rama_Ronny/entornos/sistema/lib/python3.10/site-packages/django_crontab/crontab.py", line 126, in run_job
    job = self.__get_job_by_hash(job_hash)
  File "/home/ronny/Escritorio/Rama_Ronny/entornos/sistema/lib/python3.10/site-packages/django_crontab/crontab.py", line 171, in __get_job_by_hash
    raise RuntimeError(
RuntimeError: No job with hash 2b81aae0b31c33ee9e384b4c1a5e8f01 found. It seems the crontab is out of sync with your settings.CRONJOBS. Run "python manage.py crontab add" again to resolve this issue!
Traceback (most recent call last):
  File "/home/ronny/Escritorio/Rama_Ronny/sistema_django_postgresql/manage.py", line 22, in <module>
    main()
  File "/home/ronny/Escritorio/Rama_Ronny/sistema_django_postgresql/manage.py", line 18, in main
    execute_from_command_line(sys.argv)
  File "/home/ronny/Escritorio/Rama_Ronny/entornos/sistema/lib/python3.10/site-packages/django/core/management/__init__.py", line 419, in execute_from_command_line
    utility.execute()
  File "/home/ronny/Escritorio/Rama_Ronny/entornos/sistema/lib/python3.10/site-packages/django/core/management/__init__.py", line 413, in execute
    self.fetch_command(subcommand).run_from_argv(self.argv)
  File "/home/ronny/Escritorio/Rama_Ronny/entornos/sistema/lib/python3.10/site-packages/django/core/management/base.py", line 354, in run_from_argv
    self.execute(*args, **cmd_options)
  File "/home/ronny/Escritorio/Rama_Ronny/entornos/sistema/lib/python3.10/site-packages/django/core/management/base.py", line 398, in execute
    output = self.handle(*args, **options)
  File "/home/ronny/Escritorio/Rama_Ronny/entornos/sistema/lib/python3.10/site-packages/django_crontab/management/commands/crontab.py", line 29, in handle
    Crontab().run_job(options['jobhash'])
  File "/home/ronny/Escritorio/Rama_Ronny/entornos/sistema/lib/python3.10/site-packages/django_crontab/crontab.py", line 126, in run_job
    job = self.__get_job_by_hash(job_hash)
  File "/home/ronny/Escritorio/Rama_Ronny/entornos/sistema/lib/python3.10/site-packages/django_crontab/crontab.py", line 171, in __get_job_by_hash
    raise RuntimeError(
RuntimeError: No job with hash 2b81aae0b31c33ee9e384b4c1a5e8f01 found. It seems the crontab is out of sync with your settings.CRONJOBS. Run "python manage.py crontab add" again to resolve this issue!
Traceback (most recent call last):
  File "/home/ronny/Escritorio/Rama_Ronny/sistema_django_postgresql/manage.py", line 22, in <module>
    main()
  File "/home/ronny/Escritorio/Rama_Ronny/sistema_django_postgresql/manage.py", line 18, in main
    execute_from_command_line(sys.argv)
  File "/home/ronny/Escritorio/Rama_Ronny/entornos/sistema/lib/python3.10/site-packages/django/core/management/__init__.py", line 419, in execute_from_command_line
    utility.execute()
  File "/home/ronny/Escritorio/Rama_Ronny/entornos/sistema/lib/python3.10/site-packages/django/core/management/__init__.py", line 413, in execute
    self.fetch_command(subcommand).run_from_argv(self.argv)
  File "/home/ronny/Escritorio/Rama_Ronny/entornos/sistema/lib/python3.10/site-packages/django/core/management/base.py", line 354, in run_from_argv
    self.execute(*args, **cmd_options)
  File "/home/ronny/Escritorio/Rama_Ronny/entornos/sistema/lib/python3.10/site-packages/django/core/management/base.py", line 398, in execute
    output = self.handle(*args, **options)
  File "/home/ronny/Escritorio/Rama_Ronny/entornos/sistema/lib/python3.10/site-packages/django_crontab/management/commands/crontab.py", line 29, in handle
    Crontab().run_job(options['jobhash'])
  File "/home/ronny/Escritorio/Rama_Ronny/entornos/sistema/lib/python3.10/site-packages/django_crontab/crontab.py", line 126, in run_job
    job = self.__get_job_by_hash(job_hash)
  File "/home/ronny/Escritorio/Rama_Ronny/entornos/sistema/lib/python3.10/site-packages/django_crontab/crontab.py", line 171, in __get_job_by_hash
    raise RuntimeError(
RuntimeError: No job with hash 2b81aae0b31c33ee9e384b4c1a5e8f01 found. It seems the crontab is out of sync with your settings.CRONJOBS. Run "python manage.py crontab add" again to resolve this issue!
Traceback (most recent call last):
  File "/home/ronny/Escritorio/Rama_Ronny/sistema_django_postgresql/manage.py", line 22, in <module>
    main()
  File "/home/ronny/Escritorio/Rama_Ronny/sistema_django_postgresql/manage.py", line 18, in main
    execute_from_command_line(sys.argv)
  File "/home/ronny/Escritorio/Rama_Ronny/entornos/sistema/lib/python3.10/site-packages/django/core/management/__init__.py", line 419, in execute_from_command_line
    utility.execute()
  File "/home/ronny/Escritorio/Rama_Ronny/entornos/sistema/lib/python3.10/site-packages/django/core/management/__init__.py", line 413, in execute
    self.fetch_command(subcommand).run_from_argv(self.argv)
  File "/home/ronny/Escritorio/Rama_Ronny/entornos/sistema/lib/python3.10/site-packages/django/core/management/base.py", line 354, in run_from_argv
    self.execute(*args, **cmd_options)
  File "/home/ronny/Escritorio/Rama_Ronny/entornos/sistema/lib/python3.10/site-packages/django/core/management/base.py", line 398, in execute
    output = self.handle(*args, **options)
  File "/home/ronny/Escritorio/Rama_Ronny/entornos/sistema/lib/python3.10/site-packages/django_crontab/management/commands/crontab.py", line 29, in handle
    Crontab().run_job(options['jobhash'])
  File "/home/ronny/Escritorio/Rama_Ronny/entornos/sistema/lib/python3.10/site-packages/django_crontab/crontab.py", line 126, in run_job
    job = self.__get_job_by_hash(job_hash)
  File "/home/ronny/Escritorio/Rama_Ronny/entornos/sistema/lib/python3.10/site-packages/django_crontab/crontab.py", line 171, in __get_job_by_hash
    raise RuntimeError(
RuntimeError: No job with hash 2b81aae0b31c33ee9e384b4c1a5e8f01 found. It seems the crontab is out of sync with your settings.CRONJOBS. Run "python manage.py crontab add" again to resolve this issue!
Traceback (most recent call last):
  File "/home/ronny/Escritorio/Rama_Ronny/sistema_django_postgresql/manage.py", line 22, in <module>
    main()
  File "/home/ronny/Escritorio/Rama_Ronny/sistema_django_postgresql/manage.py", line 18, in main
    execute_from_command_line(sys.argv)
  File "/home/ronny/Escritorio/Rama_Ronny/entornos/sistema/lib/python3.10/site-packages/django/core/management/__init__.py", line 419, in execute_from_command_line
    utility.execute()
  File "/home/ronny/Escritorio/Rama_Ronny/entornos/sistema/lib/python3.10/site-packages/django/core/management/__init__.py", line 413, in execute
    self.fetch_command(subcommand).run_from_argv(self.argv)
  File "/home/ronny/Escritorio/Rama_Ronny/entornos/sistema/lib/python3.10/site-packages/django/core/management/base.py", line 354, in run_from_argv
    self.execute(*args, **cmd_options)
  File "/home/ronny/Escritorio/Rama_Ronny/entornos/sistema/lib/python3.10/site-packages/django/core/management/base.py", line 393, in execute
    self.check()
  File "/home/ronny/Escritorio/Rama_Ronny/entornos/sistema/lib/python3.10/site-packages/django/core/management/base.py", line 419, in check
    all_issues = checks.run_checks(
  File "/home/ronny/Escritorio/Rama_Ronny/entornos/sistema/lib/python3.10/site-packages/django/core/checks/registry.py", line 76, in run_checks
    new_errors = check(app_configs=app_configs, databases=databases)
  File "/home/ronny/Escritorio/Rama_Ronny/entornos/sistema/lib/python3.10/site-packages/django/core/checks/urls.py", line 13, in check_url_config
    return check_resolver(resolver)
  File "/home/ronny/Escritorio/Rama_Ronny/entornos/sistema/lib/python3.10/site-packages/django/core/checks/urls.py", line 23, in check_resolver
    return check_method()
  File "/home/ronny/Escritorio/Rama_Ronny/entornos/sistema/lib/python3.10/site-packages/django/urls/resolvers.py", line 416, in check
    for pattern in self.url_patterns:
  File "/home/ronny/Escritorio/Rama_Ronny/entornos/sistema/lib/python3.10/site-packages/django/utils/functional.py", line 48, in __get__
    res = instance.__dict__[self.name] = self.func(instance)
  File "/home/ronny/Escritorio/Rama_Ronny/entornos/sistema/lib/python3.10/site-packages/django/urls/resolvers.py", line 602, in url_patterns
    patterns = getattr(self.urlconf_module, "urlpatterns", self.urlconf_module)
  File "/home/ronny/Escritorio/Rama_Ronny/entornos/sistema/lib/python3.10/site-packages/django/utils/functional.py", line 48, in __get__
    res = instance.__dict__[self.name] = self.func(instance)
  File "/home/ronny/Escritorio/Rama_Ronny/entornos/sistema/lib/python3.10/site-packages/django/urls/resolvers.py", line 595, in urlconf_module
    return import_module(self.urlconf_name)
  File "/usr/lib/python3.10/importlib/__init__.py", line 126, in import_module
    return _bootstrap._gcd_import(name[level:], package, level)
  File "<frozen importlib._bootstrap>", line 1050, in _gcd_import
  File "<frozen importlib._bootstrap>", line 1027, in _find_and_load
  File "<frozen importlib._bootstrap>", line 1006, in _find_and_load_unlocked
  File "<frozen importlib._bootstrap>", line 688, in _load_unlocked
  File "<frozen importlib._bootstrap_external>", line 883, in exec_module
  File "<frozen importlib._bootstrap>", line 241, in _call_with_frames_removed
  File "/home/ronny/Escritorio/Rama_Ronny/sistema_django_postgresql/sistema_django_postgresql/urls.py", line 43, in <module>
    path('reportes/', include('applications.reportes.urls')),
  File "/home/ronny/Escritorio/Rama_Ronny/entornos/sistema/lib/python3.10/site-packages/django/urls/conf.py", line 34, in include
    urlconf_module = import_module(urlconf_module)
  File "/usr/lib/python3.10/importlib/__init__.py", line 126, in import_module
    return _bootstrap._gcd_import(name[level:], package, level)
  File "<frozen importlib._bootstrap>", line 1050, in _gcd_import
  File "<frozen importlib._bootstrap>", line 1027, in _find_and_load
  File "<frozen importlib._bootstrap>", line 1006, in _find_and_load_unlocked
  File "<frozen importlib._bootstrap>", line 688, in _load_unlocked
  File "<frozen importlib._bootstrap_external>", line 883, in exec_module
  File "<frozen importlib._bootstrap>", line 241, in _call_with_frames_removed
  File "/home/ronny/Escritorio/Rama_Ronny/sistema_django_postgresql/applications/reportes/urls.py", line 8, in <module>
    path('reportes-crm/cliente-crm/', views.ReporteClienteCRM.as_view(), name='reporte_cliente_crm'),
AttributeError: module 'applications.reportes.views' has no attribute 'ReporteClienteCRM'
Traceback (most recent call last):
  File "/home/ronny/Escritorio/Rama_Ronny/sistema_django_postgresql/manage.py", line 22, in <module>
    main()
  File "/home/ronny/Escritorio/Rama_Ronny/sistema_django_postgresql/manage.py", line 18, in main
    execute_from_command_line(sys.argv)
  File "/home/ronny/Escritorio/Rama_Ronny/entornos/sistema/lib/python3.10/site-packages/django/core/management/__init__.py", line 419, in execute_from_command_line
    utility.execute()
  File "/home/ronny/Escritorio/Rama_Ronny/entornos/sistema/lib/python3.10/site-packages/django/core/management/__init__.py", line 413, in execute
    self.fetch_command(subcommand).run_from_argv(self.argv)
  File "/home/ronny/Escritorio/Rama_Ronny/entornos/sistema/lib/python3.10/site-packages/django/core/management/base.py", line 354, in run_from_argv
    self.execute(*args, **cmd_options)
  File "/home/ronny/Escritorio/Rama_Ronny/entornos/sistema/lib/python3.10/site-packages/django/core/management/base.py", line 398, in execute
    output = self.handle(*args, **options)
  File "/home/ronny/Escritorio/Rama_Ronny/entornos/sistema/lib/python3.10/site-packages/django_crontab/management/commands/crontab.py", line 29, in handle
    Crontab().run_job(options['jobhash'])
  File "/home/ronny/Escritorio/Rama_Ronny/entornos/sistema/lib/python3.10/site-packages/django_crontab/crontab.py", line 126, in run_job
    job = self.__get_job_by_hash(job_hash)
  File "/home/ronny/Escritorio/Rama_Ronny/entornos/sistema/lib/python3.10/site-packages/django_crontab/crontab.py", line 171, in __get_job_by_hash
    raise RuntimeError(
RuntimeError: No job with hash 2b81aae0b31c33ee9e384b4c1a5e8f01 found. It seems the crontab is out of sync with your settings.CRONJOBS. Run "python manage.py crontab add" again to resolve this issue!
Traceback (most recent call last):
  File "/home/ronny/Escritorio/Rama_Ronny/sistema_django_postgresql/manage.py", line 22, in <module>
    main()
  File "/home/ronny/Escritorio/Rama_Ronny/sistema_django_postgresql/manage.py", line 18, in main
    execute_from_command_line(sys.argv)
  File "/home/ronny/Escritorio/Rama_Ronny/entornos/sistema/lib/python3.10/site-packages/django/core/management/__init__.py", line 419, in execute_from_command_line
    utility.execute()
  File "/home/ronny/Escritorio/Rama_Ronny/entornos/sistema/lib/python3.10/site-packages/django/core/management/__init__.py", line 413, in execute
    self.fetch_command(subcommand).run_from_argv(self.argv)
  File "/home/ronny/Escritorio/Rama_Ronny/entornos/sistema/lib/python3.10/site-packages/django/core/management/base.py", line 354, in run_from_argv
    self.execute(*args, **cmd_options)
  File "/home/ronny/Escritorio/Rama_Ronny/entornos/sistema/lib/python3.10/site-packages/django/core/management/base.py", line 398, in execute
    output = self.handle(*args, **options)
  File "/home/ronny/Escritorio/Rama_Ronny/entornos/sistema/lib/python3.10/site-packages/django_crontab/management/commands/crontab.py", line 29, in handle
    Crontab().run_job(options['jobhash'])
  File "/home/ronny/Escritorio/Rama_Ronny/entornos/sistema/lib/python3.10/site-packages/django_crontab/crontab.py", line 126, in run_job
    job = self.__get_job_by_hash(job_hash)
  File "/home/ronny/Escritorio/Rama_Ronny/entornos/sistema/lib/python3.10/site-packages/django_crontab/crontab.py", line 171, in __get_job_by_hash
    raise RuntimeError(
RuntimeError: No job with hash 2b81aae0b31c33ee9e384b4c1a5e8f01 found. It seems the crontab is out of sync with your settings.CRONJOBS. Run "python manage.py crontab add" again to resolve this issue!
Traceback (most recent call last):
  File "/home/ronny/Escritorio/Rama_Ronny/sistema_django_postgresql/manage.py", line 22, in <module>
    main()
  File "/home/ronny/Escritorio/Rama_Ronny/sistema_django_postgresql/manage.py", line 18, in main
    execute_from_command_line(sys.argv)
  File "/home/ronny/Escritorio/Rama_Ronny/entornos/sistema/lib/python3.10/site-packages/django/core/management/__init__.py", line 419, in execute_from_command_line
    utility.execute()
  File "/home/ronny/Escritorio/Rama_Ronny/entornos/sistema/lib/python3.10/site-packages/django/core/management/__init__.py", line 413, in execute
    self.fetch_command(subcommand).run_from_argv(self.argv)
  File "/home/ronny/Escritorio/Rama_Ronny/entornos/sistema/lib/python3.10/site-packages/django/core/management/base.py", line 354, in run_from_argv
    self.execute(*args, **cmd_options)
  File "/home/ronny/Escritorio/Rama_Ronny/entornos/sistema/lib/python3.10/site-packages/django/core/management/base.py", line 393, in execute
    self.check()
  File "/home/ronny/Escritorio/Rama_Ronny/entornos/sistema/lib/python3.10/site-packages/django/core/management/base.py", line 419, in check
    all_issues = checks.run_checks(
  File "/home/ronny/Escritorio/Rama_Ronny/entornos/sistema/lib/python3.10/site-packages/django/core/checks/registry.py", line 76, in run_checks
    new_errors = check(app_configs=app_configs, databases=databases)
  File "/home/ronny/Escritorio/Rama_Ronny/entornos/sistema/lib/python3.10/site-packages/django/core/checks/urls.py", line 13, in check_url_config
    return check_resolver(resolver)
  File "/home/ronny/Escritorio/Rama_Ronny/entornos/sistema/lib/python3.10/site-packages/django/core/checks/urls.py", line 23, in check_resolver
    return check_method()
  File "/home/ronny/Escritorio/Rama_Ronny/entornos/sistema/lib/python3.10/site-packages/django/urls/resolvers.py", line 416, in check
    for pattern in self.url_patterns:
  File "/home/ronny/Escritorio/Rama_Ronny/entornos/sistema/lib/python3.10/site-packages/django/utils/functional.py", line 48, in __get__
    res = instance.__dict__[self.name] = self.func(instance)
  File "/home/ronny/Escritorio/Rama_Ronny/entornos/sistema/lib/python3.10/site-packages/django/urls/resolvers.py", line 602, in url_patterns
    patterns = getattr(self.urlconf_module, "urlpatterns", self.urlconf_module)
  File "/home/ronny/Escritorio/Rama_Ronny/entornos/sistema/lib/python3.10/site-packages/django/utils/functional.py", line 48, in __get__
    res = instance.__dict__[self.name] = self.func(instance)
  File "/home/ronny/Escritorio/Rama_Ronny/entornos/sistema/lib/python3.10/site-packages/django/urls/resolvers.py", line 595, in urlconf_module
    return import_module(self.urlconf_name)
  File "/usr/lib/python3.10/importlib/__init__.py", line 126, in import_module
    return _bootstrap._gcd_import(name[level:], package, level)
  File "<frozen importlib._bootstrap>", line 1050, in _gcd_import
  File "<frozen importlib._bootstrap>", line 1027, in _find_and_load
  File "<frozen importlib._bootstrap>", line 1006, in _find_and_load_unlocked
  File "<frozen importlib._bootstrap>", line 688, in _load_unlocked
  File "<frozen importlib._bootstrap_external>", line 883, in exec_module
  File "<frozen importlib._bootstrap>", line 241, in _call_with_frames_removed
  File "/home/ronny/Escritorio/Rama_Ronny/sistema_django_postgresql/sistema_django_postgresql/urls.py", line 43, in <module>
    path('reportes/', include('applications.reportes.urls')),
  File "/home/ronny/Escritorio/Rama_Ronny/entornos/sistema/lib/python3.10/site-packages/django/urls/conf.py", line 34, in include
    urlconf_module = import_module(urlconf_module)
  File "/usr/lib/python3.10/importlib/__init__.py", line 126, in import_module
    return _bootstrap._gcd_import(name[level:], package, level)
  File "<frozen importlib._bootstrap>", line 1050, in _gcd_import
  File "<frozen importlib._bootstrap>", line 1027, in _find_and_load
  File "<frozen importlib._bootstrap>", line 1006, in _find_and_load_unlocked
  File "<frozen importlib._bootstrap>", line 688, in _load_unlocked
  File "<frozen importlib._bootstrap_external>", line 883, in exec_module
  File "<frozen importlib._bootstrap>", line 241, in _call_with_frames_removed
  File "/home/ronny/Escritorio/Rama_Ronny/sistema_django_postgresql/applications/reportes/urls.py", line 2, in <module>
    from . import views
  File "/home/ronny/Escritorio/Rama_Ronny/sistema_django_postgresql/applications/reportes/views.py", line 31, in <module>
    from applications.reportes.excel import generarReporteFacturacionAsesorComercial
ImportError: cannot import name 'generarReporteFacturacionAsesorComercial' from 'applications.reportes.excel' (/home/ronny/Escritorio/Rama_Ronny/sistema_django_postgresql/applications/reportes/excel.py)
Traceback (most recent call last):
  File "/home/ronny/Escritorio/Rama_Ronny/sistema_django_postgresql/manage.py", line 22, in <module>
    main()
  File "/home/ronny/Escritorio/Rama_Ronny/sistema_django_postgresql/manage.py", line 18, in main
    execute_from_command_line(sys.argv)
  File "/home/ronny/Escritorio/Rama_Ronny/entornos/sistema/lib/python3.10/site-packages/django/core/management/__init__.py", line 419, in execute_from_command_line
    utility.execute()
  File "/home/ronny/Escritorio/Rama_Ronny/entornos/sistema/lib/python3.10/site-packages/django/core/management/__init__.py", line 413, in execute
    self.fetch_command(subcommand).run_from_argv(self.argv)
  File "/home/ronny/Escritorio/Rama_Ronny/entornos/sistema/lib/python3.10/site-packages/django/core/management/base.py", line 354, in run_from_argv
    self.execute(*args, **cmd_options)
  File "/home/ronny/Escritorio/Rama_Ronny/entornos/sistema/lib/python3.10/site-packages/django/core/management/base.py", line 398, in execute
    output = self.handle(*args, **options)
  File "/home/ronny/Escritorio/Rama_Ronny/entornos/sistema/lib/python3.10/site-packages/django_crontab/management/commands/crontab.py", line 29, in handle
    Crontab().run_job(options['jobhash'])
  File "/home/ronny/Escritorio/Rama_Ronny/entornos/sistema/lib/python3.10/site-packages/django_crontab/crontab.py", line 126, in run_job
    job = self.__get_job_by_hash(job_hash)
  File "/home/ronny/Escritorio/Rama_Ronny/entornos/sistema/lib/python3.10/site-packages/django_crontab/crontab.py", line 171, in __get_job_by_hash
    raise RuntimeError(
RuntimeError: No job with hash 2b81aae0b31c33ee9e384b4c1a5e8f01 found. It seems the crontab is out of sync with your settings.CRONJOBS. Run "python manage.py crontab add" again to resolve this issue!
Traceback (most recent call last):
  File "/home/ronny/Escritorio/Rama_Ronny/sistema_django_postgresql/manage.py", line 22, in <module>
    main()
  File "/home/ronny/Escritorio/Rama_Ronny/sistema_django_postgresql/manage.py", line 18, in main
    execute_from_command_line(sys.argv)
  File "/home/ronny/Escritorio/Rama_Ronny/entornos/sistema/lib/python3.10/site-packages/django/core/management/__init__.py", line 419, in execute_from_command_line
    utility.execute()
  File "/home/ronny/Escritorio/Rama_Ronny/entornos/sistema/lib/python3.10/site-packages/django/core/management/__init__.py", line 413, in execute
    self.fetch_command(subcommand).run_from_argv(self.argv)
  File "/home/ronny/Escritorio/Rama_Ronny/entornos/sistema/lib/python3.10/site-packages/django/core/management/base.py", line 354, in run_from_argv
    self.execute(*args, **cmd_options)
  File "/home/ronny/Escritorio/Rama_Ronny/entornos/sistema/lib/python3.10/site-packages/django/core/management/base.py", line 398, in execute
    output = self.handle(*args, **options)
  File "/home/ronny/Escritorio/Rama_Ronny/entornos/sistema/lib/python3.10/site-packages/django_crontab/management/commands/crontab.py", line 29, in handle
    Crontab().run_job(options['jobhash'])
  File "/home/ronny/Escritorio/Rama_Ronny/entornos/sistema/lib/python3.10/site-packages/django_crontab/crontab.py", line 126, in run_job
    job = self.__get_job_by_hash(job_hash)
  File "/home/ronny/Escritorio/Rama_Ronny/entornos/sistema/lib/python3.10/site-packages/django_crontab/crontab.py", line 171, in __get_job_by_hash
    raise RuntimeError(
RuntimeError: No job with hash 2b81aae0b31c33ee9e384b4c1a5e8f01 found. It seems the crontab is out of sync with your settings.CRONJOBS. Run "python manage.py crontab add" again to resolve this issue!
Traceback (most recent call last):
  File "/home/ronny/Escritorio/Rama_Ronny/sistema_django_postgresql/manage.py", line 22, in <module>
    main()
  File "/home/ronny/Escritorio/Rama_Ronny/sistema_django_postgresql/manage.py", line 18, in main
    execute_from_command_line(sys.argv)
  File "/home/ronny/Escritorio/Rama_Ronny/entornos/sistema/lib/python3.10/site-packages/django/core/management/__init__.py", line 419, in execute_from_command_line
    utility.execute()
  File "/home/ronny/Escritorio/Rama_Ronny/entornos/sistema/lib/python3.10/site-packages/django/core/management/__init__.py", line 413, in execute
    self.fetch_command(subcommand).run_from_argv(self.argv)
  File "/home/ronny/Escritorio/Rama_Ronny/entornos/sistema/lib/python3.10/site-packages/django/core/management/base.py", line 354, in run_from_argv
    self.execute(*args, **cmd_options)
  File "/home/ronny/Escritorio/Rama_Ronny/entornos/sistema/lib/python3.10/site-packages/django/core/management/base.py", line 398, in execute
    output = self.handle(*args, **options)
  File "/home/ronny/Escritorio/Rama_Ronny/entornos/sistema/lib/python3.10/site-packages/django_crontab/management/commands/crontab.py", line 29, in handle
    Crontab().run_job(options['jobhash'])
  File "/home/ronny/Escritorio/Rama_Ronny/entornos/sistema/lib/python3.10/site-packages/django_crontab/crontab.py", line 126, in run_job
    job = self.__get_job_by_hash(job_hash)
  File "/home/ronny/Escritorio/Rama_Ronny/entornos/sistema/lib/python3.10/site-packages/django_crontab/crontab.py", line 171, in __get_job_by_hash
    raise RuntimeError(
RuntimeError: No job with hash 2b81aae0b31c33ee9e384b4c1a5e8f01 found. It seems the crontab is out of sync with your settings.CRONJOBS. Run "python manage.py crontab add" again to resolve this issue!
Traceback (most recent call last):
  File "/home/ronny/Escritorio/Rama_Ronny/sistema_django_postgresql/manage.py", line 22, in <module>
    main()
  File "/home/ronny/Escritorio/Rama_Ronny/sistema_django_postgresql/manage.py", line 18, in main
    execute_from_command_line(sys.argv)
  File "/home/ronny/Escritorio/Rama_Ronny/entornos/sistema/lib/python3.10/site-packages/django/core/management/__init__.py", line 419, in execute_from_command_line
    utility.execute()
  File "/home/ronny/Escritorio/Rama_Ronny/entornos/sistema/lib/python3.10/site-packages/django/core/management/__init__.py", line 413, in execute
    self.fetch_command(subcommand).run_from_argv(self.argv)
  File "/home/ronny/Escritorio/Rama_Ronny/entornos/sistema/lib/python3.10/site-packages/django/core/management/base.py", line 354, in run_from_argv
    self.execute(*args, **cmd_options)
  File "/home/ronny/Escritorio/Rama_Ronny/entornos/sistema/lib/python3.10/site-packages/django/core/management/base.py", line 398, in execute
    output = self.handle(*args, **options)
  File "/home/ronny/Escritorio/Rama_Ronny/entornos/sistema/lib/python3.10/site-packages/django_crontab/management/commands/crontab.py", line 29, in handle
    Crontab().run_job(options['jobhash'])
  File "/home/ronny/Escritorio/Rama_Ronny/entornos/sistema/lib/python3.10/site-packages/django_crontab/crontab.py", line 126, in run_job
    job = self.__get_job_by_hash(job_hash)
  File "/home/ronny/Escritorio/Rama_Ronny/entornos/sistema/lib/python3.10/site-packages/django_crontab/crontab.py", line 171, in __get_job_by_hash
    raise RuntimeError(
RuntimeError: No job with hash 2b81aae0b31c33ee9e384b4c1a5e8f01 found. It seems the crontab is out of sync with your settings.CRONJOBS. Run "python manage.py crontab add" again to resolve this issue!
