actualizar_estado_cliente_crm
Traceback (most recent call last):
  File "/home/ronny/Escritorio/Rama_Ronny/sistema_django_postgresql/manage.py", line 22, in <module>
    main()
  File "/home/ronny/Escritorio/Rama_Ronny/sistema_django_postgresql/manage.py", line 18, in main
    execute_from_command_line(sys.argv)
  File "/home/ronny/Escritorio/Rama_Ronny/entornos/sistema/lib/python3.10/site-packages/django/core/management/__init__.py", line 419, in execute_from_command_line
    utility.execute()
  File "/home/ronny/Escritorio/Rama_Ronny/entornos/sistema/lib/python3.10/site-packages/django/core/management/__init__.py", line 413, in execute
    self.fetch_command(subcommand).run_from_argv(self.argv)
  File "/home/ronny/Escritorio/Rama_Ronny/entornos/sistema/lib/python3.10/site-packages/django/core/management/base.py", line 354, in run_from_argv
    self.execute(*args, **cmd_options)
  File "/home/ronny/Escritorio/Rama_Ronny/entornos/sistema/lib/python3.10/site-packages/django/core/management/base.py", line 398, in execute
    output = self.handle(*args, **options)
  File "/home/ronny/Escritorio/Rama_Ronny/entornos/sistema/lib/python3.10/site-packages/django_crontab/management/commands/crontab.py", line 29, in handle
    Crontab().run_job(options['jobhash'])
  File "/home/ronny/Escritorio/Rama_Ronny/entornos/sistema/lib/python3.10/site-packages/django_crontab/crontab.py", line 126, in run_job
    job = self.__get_job_by_hash(job_hash)
  File "/home/ronny/Escritorio/Rama_Ronny/entornos/sistema/lib/python3.10/site-packages/django_crontab/crontab.py", line 171, in __get_job_by_hash
    raise RuntimeError(
RuntimeError: No job with hash 2b81aae0b31c33ee9e384b4c1a5e8f01 found. It seems the crontab is out of sync with your settings.CRONJOBS. Run "python manage.py crontab add" again to resolve this issue!
Traceback (most recent call last):
  File "/home/ronny/Escritorio/Rama_Ronny/sistema_django_postgresql/manage.py", line 22, in <module>
    main()
  File "/home/ronny/Escritorio/Rama_Ronny/sistema_django_postgresql/manage.py", line 18, in main
    execute_from_command_line(sys.argv)
  File "/home/ronny/Escritorio/Rama_Ronny/entornos/sistema/lib/python3.10/site-packages/django/core/management/__init__.py", line 419, in execute_from_command_line
    utility.execute()
  File "/home/ronny/Escritorio/Rama_Ronny/entornos/sistema/lib/python3.10/site-packages/django/core/management/__init__.py", line 413, in execute
    self.fetch_command(subcommand).run_from_argv(self.argv)
  File "/home/ronny/Escritorio/Rama_Ronny/entornos/sistema/lib/python3.10/site-packages/django/core/management/base.py", line 354, in run_from_argv
    self.execute(*args, **cmd_options)
  File "/home/ronny/Escritorio/Rama_Ronny/entornos/sistema/lib/python3.10/site-packages/django/core/management/base.py", line 398, in execute
    output = self.handle(*args, **options)
  File "/home/ronny/Escritorio/Rama_Ronny/entornos/sistema/lib/python3.10/site-packages/django_crontab/management/commands/crontab.py", line 29, in handle
    Crontab().run_job(options['jobhash'])
  File "/home/ronny/Escritorio/Rama_Ronny/entornos/sistema/lib/python3.10/site-packages/django_crontab/crontab.py", line 126, in run_job
    job = self.__get_job_by_hash(job_hash)
  File "/home/ronny/Escritorio/Rama_Ronny/entornos/sistema/lib/python3.10/site-packages/django_crontab/crontab.py", line 171, in __get_job_by_hash
    raise RuntimeError(
RuntimeError: No job with hash 2b81aae0b31c33ee9e384b4c1a5e8f01 found. It seems the crontab is out of sync with your settings.CRONJOBS. Run "python manage.py crontab add" again to resolve this issue!
Traceback (most recent call last):
  File "/home/ronny/Escritorio/Rama_Ronny/sistema_django_postgresql/manage.py", line 22, in <module>
    main()
  File "/home/ronny/Escritorio/Rama_Ronny/sistema_django_postgresql/manage.py", line 18, in main
    execute_from_command_line(sys.argv)
  File "/home/ronny/Escritorio/Rama_Ronny/entornos/sistema/lib/python3.10/site-packages/django/core/management/__init__.py", line 419, in execute_from_command_line
    utility.execute()
  File "/home/ronny/Escritorio/Rama_Ronny/entornos/sistema/lib/python3.10/site-packages/django/core/management/__init__.py", line 413, in execute
    self.fetch_command(subcommand).run_from_argv(self.argv)
  File "/home/ronny/Escritorio/Rama_Ronny/entornos/sistema/lib/python3.10/site-packages/django/core/management/base.py", line 354, in run_from_argv
    self.execute(*args, **cmd_options)
  File "/home/ronny/Escritorio/Rama_Ronny/entornos/sistema/lib/python3.10/site-packages/django/core/management/base.py", line 398, in execute
    output = self.handle(*args, **options)
  File "/home/ronny/Escritorio/Rama_Ronny/entornos/sistema/lib/python3.10/site-packages/django_crontab/management/commands/crontab.py", line 29, in handle
    Crontab().run_job(options['jobhash'])
  File "/home/ronny/Escritorio/Rama_Ronny/entornos/sistema/lib/python3.10/site-packages/django_crontab/crontab.py", line 126, in run_job
    job = self.__get_job_by_hash(job_hash)
  File "/home/ronny/Escritorio/Rama_Ronny/entornos/sistema/lib/python3.10/site-packages/django_crontab/crontab.py", line 171, in __get_job_by_hash
    raise RuntimeError(
RuntimeError: No job with hash 2b81aae0b31c33ee9e384b4c1a5e8f01 found. It seems the crontab is out of sync with your settings.CRONJOBS. Run "python manage.py crontab add" again to resolve this issue!
Traceback (most recent call last):
  File "/home/ronny/Escritorio/Rama_Ronny/sistema_django_postgresql/manage.py", line 22, in <module>
    main()
  File "/home/ronny/Escritorio/Rama_Ronny/sistema_django_postgresql/manage.py", line 18, in main
    execute_from_command_line(sys.argv)
  File "/home/ronny/Escritorio/Rama_Ronny/entornos/sistema/lib/python3.10/site-packages/django/core/management/__init__.py", line 419, in execute_from_command_line
    utility.execute()
  File "/home/ronny/Escritorio/Rama_Ronny/entornos/sistema/lib/python3.10/site-packages/django/core/management/__init__.py", line 413, in execute
    self.fetch_command(subcommand).run_from_argv(self.argv)
  File "/home/ronny/Escritorio/Rama_Ronny/entornos/sistema/lib/python3.10/site-packages/django/core/management/base.py", line 354, in run_from_argv
    self.execute(*args, **cmd_options)
  File "/home/ronny/Escritorio/Rama_Ronny/entornos/sistema/lib/python3.10/site-packages/django/core/management/base.py", line 398, in execute
    output = self.handle(*args, **options)
  File "/home/ronny/Escritorio/Rama_Ronny/entornos/sistema/lib/python3.10/site-packages/django_crontab/management/commands/crontab.py", line 29, in handle
    Crontab().run_job(options['jobhash'])
  File "/home/ronny/Escritorio/Rama_Ronny/entornos/sistema/lib/python3.10/site-packages/django_crontab/crontab.py", line 126, in run_job
    job = self.__get_job_by_hash(job_hash)
  File "/home/ronny/Escritorio/Rama_Ronny/entornos/sistema/lib/python3.10/site-packages/django_crontab/crontab.py", line 171, in __get_job_by_hash
    raise RuntimeError(
RuntimeError: No job with hash 2b81aae0b31c33ee9e384b4c1a5e8f01 found. It seems the crontab is out of sync with your settings.CRONJOBS. Run "python manage.py crontab add" again to resolve this issue!
Traceback (most recent call last):
  File "/home/ronny/Escritorio/Rama_Ronny/sistema_django_postgresql/manage.py", line 22, in <module>
    main()
  File "/home/ronny/Escritorio/Rama_Ronny/sistema_django_postgresql/manage.py", line 18, in main
    execute_from_command_line(sys.argv)
  File "/home/ronny/Escritorio/Rama_Ronny/entornos/sistema/lib/python3.10/site-packages/django/core/management/__init__.py", line 419, in execute_from_command_line
    utility.execute()
  File "/home/ronny/Escritorio/Rama_Ronny/entornos/sistema/lib/python3.10/site-packages/django/core/management/__init__.py", line 413, in execute
    self.fetch_command(subcommand).run_from_argv(self.argv)
  File "/home/ronny/Escritorio/Rama_Ronny/entornos/sistema/lib/python3.10/site-packages/django/core/management/base.py", line 354, in run_from_argv
    self.execute(*args, **cmd_options)
  File "/home/ronny/Escritorio/Rama_Ronny/entornos/sistema/lib/python3.10/site-packages/django/core/management/base.py", line 398, in execute
    output = self.handle(*args, **options)
  File "/home/ronny/Escritorio/Rama_Ronny/entornos/sistema/lib/python3.10/site-packages/django_crontab/management/commands/crontab.py", line 29, in handle
    Crontab().run_job(options['jobhash'])
  File "/home/ronny/Escritorio/Rama_Ronny/entornos/sistema/lib/python3.10/site-packages/django_crontab/crontab.py", line 126, in run_job
    job = self.__get_job_by_hash(job_hash)
  File "/home/ronny/Escritorio/Rama_Ronny/entornos/sistema/lib/python3.10/site-packages/django_crontab/crontab.py", line 171, in __get_job_by_hash
    raise RuntimeError(
RuntimeError: No job with hash 2b81aae0b31c33ee9e384b4c1a5e8f01 found. It seems the crontab is out of sync with your settings.CRONJOBS. Run "python manage.py crontab add" again to resolve this issue!
Traceback (most recent call last):
  File "/home/ronny/Escritorio/Rama_Ronny/sistema_django_postgresql/manage.py", line 22, in <module>
    main()
  File "/home/ronny/Escritorio/Rama_Ronny/sistema_django_postgresql/manage.py", line 18, in main
    execute_from_command_line(sys.argv)
  File "/home/ronny/Escritorio/Rama_Ronny/entornos/sistema/lib/python3.10/site-packages/django/core/management/__init__.py", line 419, in execute_from_command_line
    utility.execute()
  File "/home/ronny/Escritorio/Rama_Ronny/entornos/sistema/lib/python3.10/site-packages/django/core/management/__init__.py", line 413, in execute
    self.fetch_command(subcommand).run_from_argv(self.argv)
  File "/home/ronny/Escritorio/Rama_Ronny/entornos/sistema/lib/python3.10/site-packages/django/core/management/base.py", line 354, in run_from_argv
    self.execute(*args, **cmd_options)
  File "/home/ronny/Escritorio/Rama_Ronny/entornos/sistema/lib/python3.10/site-packages/django/core/management/base.py", line 398, in execute
    output = self.handle(*args, **options)
  File "/home/ronny/Escritorio/Rama_Ronny/entornos/sistema/lib/python3.10/site-packages/django_crontab/management/commands/crontab.py", line 29, in handle
    Crontab().run_job(options['jobhash'])
  File "/home/ronny/Escritorio/Rama_Ronny/entornos/sistema/lib/python3.10/site-packages/django_crontab/crontab.py", line 126, in run_job
    job = self.__get_job_by_hash(job_hash)
  File "/home/ronny/Escritorio/Rama_Ronny/entornos/sistema/lib/python3.10/site-packages/django_crontab/crontab.py", line 171, in __get_job_by_hash
    raise RuntimeError(
RuntimeError: No job with hash 2b81aae0b31c33ee9e384b4c1a5e8f01 found. It seems the crontab is out of sync with your settings.CRONJOBS. Run "python manage.py crontab add" again to resolve this issue!
